<robot name="arm95" version="1.0">
  <joint name="Joint1" type="revolute">
    <limit lower="-3.14" upper="3.14" effort="143.00000" velocity="3.14000"/>
    <origin rpy="-3.14159 0.00000 0.00000" xyz="0.00000 0.00000 0.09000"/>
    <parent link="Base_link"/>
    <child link="Link1"/>
    <axis xyz="0.00000 0.00000 -1.00000"/>
  </joint>
  <joint name="Joint2" type="revolute">
    <limit lower="-3.14" upper="3.14" effort="143.00000" velocity="3.14000"/>
    <origin rpy="1.57080 0.00000 0.00000" xyz="0.00000 0.09100 -0.08000"/>
    <parent link="Link1"/>
    <child link="Link2"/>
    <axis xyz="0.00000 0.00000 1.00000"/>
  </joint>
  <joint name="Joint3" type="revolute">
    <limit lower="-3.14" upper="3.14" effort="110.00000" velocity="3.14000"/>
    <origin rpy="0.00000 0.00000 0.00000" xyz="0.00000 -0.45999 0.01100"/>
    <parent link="Link2"/>
    <child link="Link3"/>
    <axis xyz="0.00000 0.00000 1.00000"/>
  </joint>
  <joint name="Joint4" type="revolute">
    <limit lower="-3.14" upper="3.14" effort="70.00000" velocity="3.14000"/>
    <origin rpy="0.00000 0.00000 0.00000" xyz="0.00000 -0.37999 -0.00600"/>
    <parent link="Link3"/>
    <child link="Link4"/>
    <axis xyz="0.00000 0.00000 1.00000"/>
  </joint>
  <joint name="Joint5" type="revolute">
    <limit lower="-3.14" upper="3.14" effort="70.00000" velocity="3.14000"/>
    <origin rpy="-1.57080 0.00000 0.00000" xyz="0.00000 -0.06100 -0.04900"/>
    <parent link="Link4"/>
    <child link="Link5"/>
    <axis xyz="0.00000 0.00000 -1.00000"/>
  </joint>
  <joint name="Joint6" type="revolute">
    <limit lower="-3.14" upper="3.14" effort="70.00000" velocity="3.14000"/>
    <origin rpy="1.57080 0.00000 0.00000" xyz="0.00000 0.06100 -0.04900"/>
    <parent link="Link5"/>
    <child link="Link6"/>
    <axis xyz="0.00000 0.00000 1.00000"/>
  </joint>
  <link name="Base_link">
    <collision name="Base_collision">
      <origin rpy="0.00000 0.00000 0.00000" xyz="0.00000 0.00000 0.00000"/>
      <geometry>
        <mesh filename="package://arm95_description/resource/meshes/visual/Base.stl" scale="1.00000 1.00000 1.00000"/>
      </geometry>
    </collision>
    <inertial>
      <inertia ixx="0.02436" ixy="-0.00013" ixz="-0.00207" iyy="0.03078" iyz="-0.00115" izz="0.01120"/>
      <origin rpy="0.00000 0.00000 0.00000" xyz="-0.00107 -0.01167 0.02457"/>
      <mass value="4.00000"/>
    </inertial>
    <visual name="Base">
      <origin rpy="0.00000 0.00000 0.00000" xyz="0.00000 0.00000 0.00000"/>
      <material name="Base"/>
      <geometry>
        <mesh filename="package://arm95_description/resource/meshes/visual/Base.stl" scale="1.00000 1.00000 1.00000"/>
      </geometry>
    </visual>
  </link>
  <link name="Link1">
    <collision name="Link1_collision">
      <origin rpy="3.14159 0.00000 0.00000" xyz="0.00000 0.00000 0.00000"/>
      <geometry>
        <mesh filename="package://arm95_description/resource/meshes/visual/Link1.stl" scale="1.00000 1.00000 1.00000"/>
      </geometry>
    </collision>
    <inertial>
      <inertia ixx="0.02188" ixy="0.00002" ixz="-0.00000" iyy="0.01139" iyz="0.00147" izz="0.02041"/>
      <origin rpy="0.00000 0.00000 0.00000" xyz="-0.00000 0.01015 -0.10757"/>
      <mass value="4.00000"/>
    </inertial>
    <visual name="Link1">
      <origin rpy="3.14159 0.00000 0.00000" xyz="0.00000 0.00000 0.00000"/>
      <material name="Base"/>
      <geometry>
        <mesh filename="package://arm95_description/resource/meshes/visual/Link1.stl" scale="1.00000 1.00000 1.00000"/>
      </geometry>
    </visual>
  </link>
  <link name="Link2">
    <collision name="Link2_collision">
      <origin rpy="1.57080 0.00000 0.00000" xyz="0.00000 0.00000 0.00000"/>
      <geometry>
        <mesh filename="package://arm95_description/resource/meshes/visual/Link2.stl" scale="1.00000 1.00000 1.00000"/>
      </geometry>
    </collision>
    <inertial>
      <inertia ixx="0.21006" ixy="-0.00002" ixz="-0.00002" iyy="0.02232" iyz="-0.01182" izz="0.19617"/>
      <origin rpy="0.00000 0.00000 0.00000" xyz="0.00000 -0.20632 -0.08278"/>
      <mass value="6.00000"/>
    </inertial>
    <visual name="Link2">
      <origin rpy="1.57080 0.00000 0.00000" xyz="0.00000 0.00000 0.00000"/>
      <material name="Base"/>
      <geometry>
        <mesh filename="package://arm95_description/resource/meshes/visual/Link2.stl" scale="1.00000 1.00000 1.00000"/>
      </geometry>
    </visual>
  </link>
  <link name="Link3">
    <collision name="Link3_collision">
      <origin rpy="1.57080 0.00000 0.00000" xyz="0.00000 -0.00000 -0.00000"/>
      <geometry>
        <mesh filename="package://arm95_description/resource/meshes/visual/Link3.stl" scale="1.00000 1.00000 1.00000"/>
      </geometry>
    </collision>
    <inertial>
      <inertia ixx="0.14615" ixy="-0.00000" ixz="0.00000" iyy="0.02392" iyz="0.01265" izz="0.12787"/>
      <origin rpy="0.00000 0.00000 0.00000" xyz="0.00000 -0.18124 0.06204"/>
      <mass value="6.00000"/>
    </inertial>
    <visual name="Link3">
      <origin rpy="1.57080 0.00000 0.00000" xyz="0.00000 -0.00000 -0.00000"/>
      <material name="Base"/>
      <geometry>
        <mesh filename="package://arm95_description/resource/meshes/visual/Link3.stl" scale="1.00000 1.00000 1.00000"/>
      </geometry>
    </visual>
  </link>
  <link name="Link4">
    <collision name="Link4_collision">
      <origin rpy="1.57080 0.00000 0.00000" xyz="0.00000 -0.00000 0.00000"/>
      <geometry>
        <mesh filename="package://arm95_description/resource/meshes/visual/Link4.stl" scale="1.00000 1.00000 1.00000"/>
      </geometry>
    </collision>
    <inertial>
      <inertia ixx="0.01267" ixy="-0.00000" ixz="-0.00000" iyy="0.00337" iyz="-0.00012" izz="0.01284"/>
      <origin rpy="0.00000 0.00000 0.00000" xyz="0.00000 0.00727 -0.04969"/>
      <mass value="3.00000"/>
    </inertial>
    <visual name="Link4">
      <origin rpy="1.57080 0.00000 0.00000" xyz="0.00000 -0.00000 0.00000"/>
      <material name="Base"/>
      <geometry>
        <mesh filename="package://arm95_description/resource/meshes/visual/Link4.stl" scale="1.00000 1.00000 1.00000"/>
      </geometry>
    </visual>
  </link>
  <link name="Link5">
    <collision name="Link5_collision">
      <origin rpy="3.14159 0.00000 0.00000" xyz="0.00000 -0.00000 0.00000"/>
      <geometry>
        <mesh filename="package://arm95_description/resource/meshes/visual/Link5.stl" scale="1.00000 1.00000 1.00000"/>
      </geometry>
    </collision>
    <inertial>
      <inertia ixx="0.00682" ixy="-0.00000" ixz="0.00000" iyy="0.00696" iyz="0.00001" izz="0.00292"/>
      <origin rpy="0.00000 0.00000 0.00000" xyz="-0.00000 0.00234 -0.04955"/>
      <mass value="3.00000"/>
    </inertial>
    <visual name="Link5">
      <origin rpy="3.14159 0.00000 0.00000" xyz="0.00000 -0.00000 0.00000"/>
      <material name="Base"/>
      <geometry>
        <mesh filename="package://arm95_description/resource/meshes/visual/Link5.stl" scale="1.00000 1.00000 1.00000"/>
      </geometry>
    </visual>
  </link>
  <link name="Link6">
    <collision name="Link6_collision">
      <origin rpy="1.57080 0.00000 0.00000" xyz="0.00000 0.00000 0.00000"/>
      <geometry>
        <mesh filename="package://arm95_description/resource/meshes/visual/Link6.stl" scale="1.00000 1.00000 1.00000"/>
      </geometry>
    </collision>
    <inertial>
      <inertia ixx="0.00018" ixy="0.00000" ixz="0.00000" iyy="0.00024" iyz="0.00000" izz="0.00018"/>
      <origin rpy="0.00000 0.00000 0.00000" xyz="-0.00000 -0.00000 0.01516"/>
      <mass value="0.50000"/>
    </inertial>
    <visual name="Link6">
      <origin rpy="1.57080 0.00000 0.00000" xyz="0.00000 0.00000 0.00000"/>
      <material name="Steel"/>
      <geometry>
        <mesh filename="package://arm95_description/resource/meshes/visual/Link6.stl" scale="1.00000 1.00000 1.00000"/>
      </geometry>
    </visual>
  </link>
  <material name="Base">
    <color rgba="0.3 0.3 0.3 1.00000"/>
  </material>

  <material name="Steel">
    <color rgba="0.6 0.6 0.6 1.0"/>
  </material>
</robot>