<?xml version="1.0"?>
<!-- created with Phobos 1.0.1 "Capricious Choutengan" -->
  <robot name="pr15">

    <link name="world"/>
    <joint name="world_fixed" type="fixed">
      <origin xyz="0.0 0.0 0.0" rpy="0 0 0"/>
      <parent link="world"/>
      <child link="pr15_base_link"/>
    </joint>


    <link name="pr15_base_link">
      <inertial>
        <origin xyz="0 0 0" rpy="0 0 0"/>
        <mass value="4.021"/>
        <inertia ixx="0.01299" ixy="0" ixz="0" iyy="0.01299" iyz="0" izz="0.02208"/>
      </inertial>
      <visual name="base_link">
        <origin xyz="0 0 0" rpy="0 0 0"/>
        <geometry>
          <mesh filename="package://pr_description/resource/meshes/visual/base_link.dae" scale="1.0 1.0 1.0"/>
        </geometry>
      </visual>
      <collision name="base_link">
        <origin xyz="0 0 0.02559" rpy="0 0 0"/>
        <geometry>
          <mesh filename="package://pr_description/resource/meshes/collision/base_link_collision.stl" scale="1.0 1.0 1.0"/>
        </geometry>
      </collision>
    </link>

    <link name="pr15_forearm_link">
      <inertial>
        <origin xyz="0 0 0" rpy="0 0 0"/>
        <mass value="2.311"/>
        <inertia ixx="0.03241" ixy="0" ixz="0" iyy="0.03123" iyz="0" izz="0.00438"/>
      </inertial>
      <visual name="forearm_link">
        <origin xyz="0 0 0" rpy="1.5708 0 0"/>
        <geometry>
          <mesh filename="package://pr_description/resource/meshes/visual/forearm_link.dae" scale="1.0 1.0 1.0"/>
        </geometry>
      </visual>
      <collision name="forearm_link">
        <origin xyz="0 0 0.0401" rpy="3.14159 0 0"/>
        <geometry>
          <mesh filename="package://pr_description/resource/meshes/collision/forearm_link_collision.stl" scale="1.0 1.0 1.0"/>
        </geometry>
      </collision>
    </link>

    <link name="pr15_shoulder_link">
      <inertial>
        <origin xyz="0 0 0" rpy="0 0 0"/>
        <mass value="3.661"/>
        <inertia ixx="0.01843" ixy="0" ixz="0" iyy="0.01419" iyz="0" izz="0.01341"/>
      </inertial>
      <visual name="shoulder_link">
        <origin xyz="0 0 0" rpy="0 0 0"/>
        <geometry>
          <mesh filename="package://pr_description/resource/meshes/visual/shoulder_link.dae" scale="1.0 1.0 1.0"/>
        </geometry>
      </visual>
      <collision name="shoulder_link">
        <origin xyz="0 -0.06036 0" rpy="1.5708 0 0"/>
        <geometry>
          <mesh filename="package://pr_description/resource/meshes/collision/shoulder_link_collision.stl" scale="1.0 1.0 1.0"/>
        </geometry>
      </collision>
    </link>

    <link name="pr15_upperarm_link">
      <inertial>
        <origin xyz="0 0 0" rpy="0 0 0"/>
        <mass value="8.341"/>
        <inertia ixx="0.30658" ixy="0" ixz="0" iyy="0.2933" iyz="0" izz="0.03147"/>
      </inertial>
      <visual name="upperarm_link">
        <origin xyz="0 0 0" rpy="1.5708 0 0"/>
        <geometry>
          <mesh filename="package://pr_description/resource/meshes/visual/upperarm_link.dae" scale="1.0 1.0 1.0"/>
        </geometry>
      </visual>
      <collision name="upperarm_link">
        <origin xyz="0 0 -0.09325" rpy="3.14159 0 0"/>
        <geometry>
          <mesh filename="package://pr_description/resource/meshes/collision/upperarm_link_collision.stl" scale="1.0 1.0 1.0"/>
        </geometry>
      </collision>
    </link>

    <link name="pr15_wrist1_link">
      <inertial>
        <origin xyz="0 0 0" rpy="0 0 0"/>
        <mass value="1.291"/>
        <inertia ixx="0.0025" ixy="0" ixz="0" iyy="0.00208" iyz="0" izz="0.00177"/>
      </inertial>
      <visual name="wrist1_link">
        <origin xyz="0 0 0" rpy="1.5708 0 0"/>
        <geometry>
          <mesh filename="package://pr_description/resource/meshes/visual/wrist1_link.dae" scale="1.0 1.0 1.0"/>
        </geometry>
      </visual>
      <collision name="wrist1_link">
        <origin xyz="0 -0.00465 -0.055" rpy="1.5708 0 0"/>
        <geometry>
          <mesh filename="package://pr_description/resource/meshes/collision/wrist1_link_collision.stl" scale="1.0 1.0 1.0"/>
        </geometry>
      </collision>
    </link>

    <link name="pr15_wrist2_link">
      <inertial>
        <origin xyz="0 0 0" rpy="0 0 0"/>
        <mass value="1.291"/>
        <inertia ixx="0.0025" ixy="0" ixz="0" iyy="0.00208" iyz="0" izz="0.00177"/>
      </inertial>
      <visual name="wrist2_link">
        <origin xyz="0 0 0" rpy="0 0 0"/>
        <geometry>
          <mesh filename="package://pr_description/resource/meshes/visual/wrist2_link.dae" scale="1.0 1.0 1.0"/>
        </geometry>
      </visual>
      <collision name="wrist2_link">
        <origin xyz="0 -0.00307 0.055" rpy="1.5708 0 0"/>
        <geometry>
          <mesh filename="package://pr_description/resource/meshes/collision/wrist2_link_collision.stl" scale="1.0 1.0 1.0"/>
        </geometry>
      </collision>
    </link>

    <link name="pr15_wrist3_link">
      <inertial>
        <origin xyz="0 0 0" rpy="0 0 0"/>
        <mass value="0.001"/>
        <inertia ixx="0.001" ixy="0" ixz="0" iyy="0.001" iyz="0" izz="0.001"/>
      </inertial>
    </link>

    <joint name="pr15_elbow_joint" type="revolute">
      <origin xyz="0 -0.46 0" rpy="0 0 0"/>
      <parent link="pr15_upperarm_link"/>
      <child link="pr15_forearm_link"/>
      <axis xyz="0 0 1.0"/>
      <limit lower="-3.14" upper="3.14" effort="0" velocity="0"/>
    </joint>

    <joint name="pr15_shoulder_pan_joint" type="revolute">
      <origin xyz="0 0 0.151" rpy="0 0 0"/>
      <parent link="pr15_base_link"/>
      <child link="pr15_shoulder_link"/>
      <axis xyz="0 0 1.0"/>
      <limit lower="-3.14" upper="3.14" effort="0" velocity="0"/>
    </joint>

    <joint name="pr15_shoulder_lift_joint" type="revolute">
      <origin xyz="0 -0.1 0" rpy="-1.5708 0 0"/>
      <parent link="pr15_shoulder_link"/>
      <child link="pr15_upperarm_link"/>
      <axis xyz="0 0 1.0"/>
      <limit lower="-3.14" upper="3.14" effort="0" velocity="0"/>
    </joint>

    <joint name="pr15_wrist1_joint" type="revolute">
      <origin xyz="0 -0.27 -0.0205" rpy="0 0 0"/>
      <parent link="pr15_forearm_link"/>
      <child link="pr15_wrist1_link"/>
      <axis xyz="0 0 1.0"/>
      <limit lower="-3.14" upper="3.14" effort="0" velocity="0"/>
    </joint>

    <joint name="pr15_wrist2_joint" type="revolute">
      <origin xyz="0 -0.065 -0.055" rpy="1.5708 0 0"/>
      <parent link="pr15_wrist1_link"/>
      <child link="pr15_wrist2_link"/>
      <axis xyz="0 0 1.0"/>
      <limit lower="-3.14" upper="3.14" effort="0" velocity="0"/>
    </joint>

    <joint name="pr15_wrist3_joint" type="revolute">
      <origin xyz="0 -0.065 0.055" rpy="-1.5708 0 0"/>
      <parent link="pr15_wrist2_link"/>
      <child link="pr15_wrist3_link"/>
      <axis xyz="0 0 1.0"/>
      <limit lower="-3.14" upper="3.14" effort="0" velocity="0"/>
    </joint>

  </robot>